{
 "cells": [
  {
   "cell_type": "markdown",
   "metadata": {},
   "source": [
    "## 错误处理"
   ]
  },
  {
   "cell_type": "markdown",
   "metadata": {},
   "source": [
    "在程序运行的过程中，如果发生了错误，可以事先约定返回一个错误代码，这样，就可以知道是否有错，以及出错的原因。在操作系统提供的调用中，返回错误码非常常见。比如打开文件的函数open()，成功时返回文件描述符（就是一个整数），出错时返回-1  \n",
    "用错误码来表示是否出错十分不便，因为函数本身应该返回的正常结果和错误码混在一起，造成调用者必须用大量的代码来判断是否出错"
   ]
  },
  {
   "cell_type": "markdown",
   "metadata": {},
   "source": [
    "### try"
   ]
  },
  {
   "cell_type": "markdown",
   "metadata": {},
   "source": [
    "高级语言通常都内置了一套try...except...finally...的错误处理机制，Python也不例外  \n",
    "当我们认为某些代码可能会出错时，就可以用try来运行这段代码，如果执行出错，则后续代码不会继续执行，而是直接跳转至错误处理代码，即except语句块，执行完except后，如果有finally语句块，则执行finally语句块，至此，执行完毕"
   ]
  },
  {
   "cell_type": "code",
   "execution_count": 4,
   "metadata": {},
   "outputs": [
    {
     "name": "stdout",
     "output_type": "stream",
     "text": [
      "try...\n",
      "result: 5.0\n",
      "finally...\n",
      "END\n"
     ]
    }
   ],
   "source": [
    "try:\n",
    "    print('try...')\n",
    "    r = 10 / 2\n",
    "    print('result:', r)\n",
    "except ZeroDivisionError as e:\n",
    "    print('except:', e)\n",
    "finally:\n",
    "    print('finally...')\n",
    "print('END')   "
   ]
  },
  {
   "cell_type": "markdown",
   "metadata": {},
   "source": [
    "你还可以猜测，错误应该有很多种类，如果发生了不同类型的错误，应该由不同的except语句块处理。没错，可以有多个except来捕获不同类型的错误  \n",
    "此外，如果没有错误发生，可以在except语句块后面加一个else，当没有错误发生时，会自动执行else语句"
   ]
  },
  {
   "cell_type": "code",
   "execution_count": 6,
   "metadata": {},
   "outputs": [
    {
     "name": "stdout",
     "output_type": "stream",
     "text": [
      "try...\n",
      "result: 5.0\n",
      "no error!\n",
      "finally...\n",
      "END\n"
     ]
    }
   ],
   "source": [
    "try:\n",
    "    print('try...')\n",
    "    r = 10 / int('2')\n",
    "    print('result:', r)\n",
    "except ValueError as e:\n",
    "    print('valueError:', e)\n",
    "except ZeroDivision as e:\n",
    "    print('ZeroDivisionError:', e)\n",
    "else:\n",
    "    print('no error!')\n",
    "finally:\n",
    "    print('finally...')\n",
    "print('END')"
   ]
  },
  {
   "cell_type": "markdown",
   "metadata": {},
   "source": [
    "Python的错误其实也是class，所有的错误类型都继承自BaseException，所以在使用except时需要注意的是，它不但捕获该类型的错误，还把其子类也“一网打尽”  \n",
    "第二个except永远也捕获不到UnicodeError，因为UnicodeError是ValueError的子类，如果有，也被第一个except给捕获了"
   ]
  },
  {
   "cell_type": "code",
   "execution_count": 8,
   "metadata": {},
   "outputs": [
    {
     "name": "stdout",
     "output_type": "stream",
     "text": [
      "try...\n",
      "ValueError\n"
     ]
    }
   ],
   "source": [
    "try:\n",
    "    print('try...')\n",
    "    r = 10 / int('a')\n",
    "    print('result:', r)\n",
    "except ValueError as e:\n",
    "    print('ValueError')\n",
    "except UnicodeError as e:\n",
    "    print('UnicodeError')"
   ]
  },
  {
   "cell_type": "markdown",
   "metadata": {},
   "source": [
    "使用try...except捕获错误还有一个巨大的好处，就是可以跨越多层调用，比如函数main()调用foo()，foo()调用bar()，结果bar()出错了，这时，只要main()捕获到了，就可以处理"
   ]
  },
  {
   "cell_type": "code",
   "execution_count": null,
   "metadata": {
    "collapsed": true
   },
   "outputs": [],
   "source": [
    "def foo(s):\n",
    "    return 10 / int(s)\n",
    "def bar(s):\n",
    "    return foo(s) * 2\n",
    "def main():\n",
    "    try:\n",
    "        bar('0')\n",
    "    except Exception as e:\n",
    "        print('')"
   ]
  }
 ],
 "metadata": {
  "kernelspec": {
   "display_name": "Python [conda env:tensorflow]",
   "language": "python",
   "name": "conda-env-tensorflow-py"
  },
  "language_info": {
   "codemirror_mode": {
    "name": "ipython",
    "version": 3
   },
   "file_extension": ".py",
   "mimetype": "text/x-python",
   "name": "python",
   "nbconvert_exporter": "python",
   "pygments_lexer": "ipython3",
   "version": "3.5.4"
  }
 },
 "nbformat": 4,
 "nbformat_minor": 2
}
